Workbook

Sheet Outreach
A1: Jurisdiction | B1: Organization | C1: Contact Name | D1: Role | E1: Email | F1: Tier | G1: Date Drafted | H1: Gmail Draft ID | I1: Sent? | J1: Replied? | K1: Follow-up Date (2 wks) | L1: Notes | M1: Last touch | N1: Status | O1: Next action
A2: TX | B2: Texas State Genealogical Society | C2: Emily Coffman Richardson | D2: President | E2: president@txsgs.org | F2: 1 | G2: 2026-08-06 | H2: r-6123661605323512792 | I2: Yes | J2: Yes | K2: 2026-08-20 | L2: Replied 2026-08-18: Busy with upcoming conference — not available now. Rufus replied with complimentary lifetime subscription offer. | M2: 2026-08-18 reply | N2: Warm — busy until Nov | O2: Circle back 2026-11-10
A3: TX (Dallas) | B3: Dallas Genealogical Society | C3: Beri Kaplan Schwitzer | D3: President | E3: president@dallasgenealogy.org | F3: 1 | G3: 2026-08-06 | H3: r4811107787055514791 | I3: Yes | J3: No | K3: 2026-08-20 | L3: ⚠️ No reply after 2 weeks — consider follow-up | N3: No reply | O3: Second-touch note (week1-followups.md template)
A4: TX (Dallas) | B4: Dallas Genealogical Society | C4: Kim Edge | D4: Director of Membership | E4: membership@dallasgenealogy.org | F4: 1 | G4: 2026-08-06 | H4: r-1959700704337531704 | I4: Yes | J4: No | K4: 2026-08-20 | L4: ⚠️ No reply after 2 weeks — consider follow-up | N4: No reply | O4: Second-touch note (week1-followups.md template)
A5: TX (Houston) | B5: Houston Genealogical Forum | C5: Frank C. Lytle | D5: President | E5: info@hgftx.org | F5: 1 | G5: 2026-08-06 | H5: r6232461793987967318 | I5: Yes | J5: No | K5: 2026-08-20 | L5: ⚠️ No reply after 2 weeks — consider follow-up | N5: No reply | O5: Second-touch note (week1-followups.md template)
A6: TX (Austin) | B6: Austin Genealogical Society | C6: Debbie Ulczynski | D6: President | E6: communications@austingenealogicalsociety.org | F6: 1 | G6: 2026-08-06 | H6: r-2786340151908735496 | I6: Yes | J6: No | K6: 2026-08-20 | L6: ⚠️ No reply after 2 weeks — consider follow-up | N6: No reply | O6: Second-touch note (week1-followups.md template)
A7: GA | B7: Georgia Genealogical Society | C7: Lillian Wingate | D7: President | E7: president@gagensociety.org | F7: 1 | G7: 2026-08-06 | H7: r2773135958402912986 | I7: Yes | J7: Yes | K7: 2026-08-20 | L7: Replied 2026-07-29: Declined — not interested. Rufus acknowledged gracefully. | N7: Declined | O7: None
A8: MN | B8: Minnesota Genealogical Society | C8: Mike Amidon | D8: President | E8: president@mngs.org | F8: 1 | G8: 2026-08-06 | H8: r4832178354393645045 | I8: Yes | J8: No | K8: 2026-08-20 | L8: ⚠️ No reply after 2 weeks — consider follow-up | N8: No reply | O8: Second-touch note (week1-followups.md template)
A9: NC | B9: North Carolina Genealogical Society | C9: David McCorkle | D9: President | E9: info@ncgenealogy.org | F9: 1 | G9: 2026-08-06 | H9: r8534923792559368331 | I9: Yes | J9: No | K9: 2026-08-20 | L9: ⚠️ No reply after 2 weeks — consider follow-up | N9: No reply | O9: Second-touch note (week1-followups.md template)
A10: NC (Charlotte) | B10: Mecklenburg GS "Olde Meck" | C10: Katie Grafer | D10: President | E10: President@oldemeck.org | F10: 1 | G10: 2026-08-06 | H10: r7180791586960514622 | I10: Yes | J10: Yes | K10: 2026-08-20 | L10: Replied 2026-08-08 via katie@diggingforroots.net: Very positive! Trial credentials sent 2026-08-09. Review meeting held 2026-08-26 4pm EDT — active tester. | M10: 2026-09-09 Rufus combined email | N10: Active tester (comped) | O10: Await Katie's newsletter answer; reconnect ~Nov
A11: NC (Raleigh) | B11: Wake County Genealogical Society | C11: Barbara McGeachy | D11: President | E11: president@wakecogen.org | F11: 1 | G11: 2026-08-06 | H11: r-3769036800251127563 | I11: Yes | J11: No | K11: 2026-08-20 | L11: ⚠️ No reply after 2 weeks — consider follow-up | N11: No reply | O11: Second-touch note (week1-followups.md template)
A12: WA | B12: Washington State Genealogical Society | C12: Kathleen (Kathy) Sizer | D12: President | E12: sizer@bentonrea.com | F12: 1 | G12: 2026-08-06 | H12: r-6715318302531636624 | I12: Yes | J12: No | K12: 2026-08-20 | L12: ⚠️ No reply after 2 weeks — consider follow-up | N12: No reply | O12: Second-touch note (week1-followups.md template)
A13: WA (Tacoma) | B13: Tacoma-Pierce County GS | C13: Tim Ward | D13: President | E13: president@tpcgs.org | F13: 1 | G13: 2026-08-06 | H13: r-3080417372529593595 | I13: Yes | J13: No | K13: 2026-08-20 | L13: ⚠️ No reply after 2 weeks — consider follow-up | N13: No reply | O13: Second-touch note (week1-followups.md template)
A14: WA (Spokane) | B14: Eastern Washington GS | C14: Dolly Gorrod Webb | D14: President | E14: President@ewgsi.org | F14: 1 | G14: 2026-08-06 | H14: r-3022120070576092471 | I14: Yes | J14: No | K14: 2026-08-20 | L14: ⚠️ No reply after 2 weeks — consider follow-up | N14: No reply | O14: Second-touch note (week1-followups.md template)
A15: NJ | B15: Genealogical Society of New Jersey | C15: Mary Szaro CG | D15: President | E15: president@gsnj.org | F15: 1 | G15: 2026-08-06 | H15: r2428190722151094001 | I15: Yes | J15: No | K15: 2026-08-20 | L15: ⚠️ No reply after 2 weeks — consider follow-up | N15: No reply | O15: Second-touch note (week1-followups.md template)
A16: NJ (Monmouth) | B16: Monmouth County Genealogy Society | C16: Carol (Fisher) Megill | D16: Roots Group Lead / Historian | E16: carolmegill@gmail.com | F16: 1 | G16: 2026-08-06 | H16: r-6471223962080742686 | I16: Yes | J16: No | K16: 2026-08-20 | L16: ⚠️ No reply after 2 weeks — consider follow-up | N16: No reply | O16: Second-touch note (week1-followups.md template)
A17: NM | B17: New Mexico Genealogical Society | C17: Henrietta Martinez Christmas | D17: President | E17: info@nmgs.org | F17: 1 | G17: 2026-08-06 | H17: r6513282555489302073 | I17: Yes | J17: No | K17: 2026-08-20 | L17: ⚠️ No reply after 2 weeks — consider follow-up | N17: No reply | O17: Second-touch note (week1-followups.md template)
A18: LA | B18: Louisiana Genealogical & Historical Society | C18: Robert Brevelle | D18: Chairman | E18: info@laghs.com | F18: 1 | G18: 2026-08-06 | H18: r-4261522493829288194 | I18: Yes | J18: No | K18: 2026-08-20 | L18: ⚠️ No reply after 2 weeks — consider follow-up | N18: No reply | O18: Second-touch note (week1-followups.md template)
A19: NV | B19: Nevada State Genealogical Society | C19: Richard Dalton | D19: President | E19: p-c-w@sbcglobal.net | F19: 1 | G19: 2026-08-06 | H19: r1339103577434508352 | I19: Yes | J19: No | K19: 2026-08-20 | L19: ⚠️ No reply after 2 weeks — consider follow-up | N19: No reply | O19: Second-touch note (week1-followups.md template)
A20: UT | B20: Utah Genealogical Association | C20: Maria Wittwer AG CG | D20: President | E20: info@ugagenealogy.org | F20: 1 | G20: 2026-08-06 | H20: r-7036922859443197822 | I20: Yes | J20: No | K20: 2026-08-20 | L20: ⚠️ No reply after 2 weeks — consider follow-up | N20: No reply; Tier 3 second approach to Crossroads editor 09-09 | O20: See Tier 3 row
A21: WI | B21: Wisconsin State Genealogical Society | C21: John Fassbender | D21: President | E21: wsgs@wsgs.org | F21: 1 | G21: 2026-08-06 | H21: r-7932058208361481133 | I21: Yes | J21: No | K21: 2026-08-20 | L21: ⚠️ No reply after 2 weeks — consider follow-up | N21: No reply | O21: Second-touch note (week1-followups.md template)
A22: WI (Milwaukee) | B22: Milwaukee County Genealogical Society | C22: Dee Howard | D22: Treasurer & Membership Chair | E22: treasurer@milwaukeegenealogy.org | F22: 1 | G22: 2026-08-06 | H22: r5610301252073316479 | I22: Yes | J22: No | K22: 2026-08-20 | L22: Name conflict noted — Dee Howard (Treasurer) is reliable contact per brief. ⚠️ No reply after 2 weeks — consider follow-up | N22: No reply | O22: Second-touch note (week1-followups.md template)
... A24: PA | B24: Genealogical Society of Pennsylvania | C24: Deborah Hoskins | D24: President (unverified) | E24: info@genpa.org | F24: 1 | G24: 2026-08-06 | H24: r-7841263554056186708 | I24: Yes | J24: No | K24: 2026-08-20 | L24: Officer name unverified — verify before sending. ⚠️ No reply after 2 weeks — consider follow-up | N24: No reply | O24: Second-touch note (week1-followups.md template)
A25: OH | B25: Ohio Genealogical Society | C25: Dorothea Martin / Noel Poirier | D25: President / Executive Director | E25: president@ogs.org | F25: 1 | G25: 2026-07-27 | I25: Yes | J25: No | K25: 2026-08-10 | L25: Contact form only — manual outreach required | M25: 2026-09-09 second email (Greene body) | N25: No reply ×2 | O25: Wait; if reply, treat as state-level door
A26: SC | B26: South Carolina Genealogical Society | C26: Mike Becknell | D26: President | E26: via scgen.org | F26: 1 | I26: No | J26: No | L26: Contact form only — manual outreach required | N26: Not sent | O26: Manual: contact form
A27: AB | B27: Alberta Genealogical Society | C27: Lynne Duigou | D27: President (verify) | E27: president@abgenealogy.ca | F27: 1 | G27: 2026-08-06 | H27: r2096330832498020132 | I27: Yes | J27: No | K27: 2026-08-20 | L27: Officer name noted as unverified — verify before sending. ⚠️ No reply after 2 weeks — consider follow-up | N27: No reply | O27: Second-touch note (week1-followups.md template)
A28: AB (Edmonton) | B28: AGS Edmonton Branch | C28: Karen Wilson | D28: President | E28: president@edmontongenealogy.ca | F28: 1 | G28: 2026-08-06 | H28: r-6380087031425423107 | I28: Yes | J28: No | K28: 2026-08-20 | L28: ⚠️ No reply after 2 weeks — consider follow-up | N28: No reply | O28: Second-touch note (week1-followups.md template)
A29: SK | B29: Saskatchewan Genealogical Society | C29: Roberta Cox / Deanne Cairns | D29: President / Executive Director | E29: sgs.board@sasktel.net | F29: 1 | G29: 2026-08-06 | H29: r-5959205942184312089 | I29: Yes | J29: No | K29: 2026-08-20 | L29: ⚠️ No reply after 2 weeks — consider follow-up | N29: No reply | O29: Second-touch note (week1-followups.md template)
A30: SK (Regina) | B30: SGS Regina Branch | C30: Christa Kaytor | D30: President | E30: sgsregina@gmail.com | F30: 1 | G30: 2026-08-06 | H30: r1465797711444511207 | I30: Yes | J30: Yes | K30: 2026-08-20 | L30: Replied 2026-08-14: Skeptical re: GEDCOM privacy. Rufus clarified app stays on-device. Awaiting further response from Christa. | M30: 2026-08-14 Rufus privacy reply | N30: Skeptical — awaiting | O30: Short nudge with privacy page link
A31: BC | B31: British Columbia Genealogical Society | C31: Linda Fleury | D31: President | E31: info@bcgs.ca | F31: 1 | G31: 2026-08-06 | H31: r7184229729181494994 | I31: Yes | J31: No | K31: 2026-08-20 | L31: ⚠️ No reply after 2 weeks — consider follow-up | N31: No reply | O31: Second-touch note (week1-followups.md template)
A32: BC (Kelowna) | B32: Kelowna & District Genealogical Society | C32: Marie Ablett | D32: Society Contact | E32: info@kdgs.ca | F32: 1 | G32: 2026-08-06 | H32: r4974606863782325300 | I32: Yes | J32: No | K32: 2026-08-20 | L32: ⚠️ No reply after 2 weeks — consider follow-up | N32: No reply | O32: Second-touch note (week1-followups.md template)
A33: QC (English) | B33: Quebec Family History Society | C33: Gary Schroder | D33: President | E33: qfhs@bellnet.ca | F33: 1 | G33: 2026-08-06 | H33: r6360648698486957912 | I33: Yes | J33: No | K33: 2026-08-20 | L33: ⚠️ No reply after 2 weeks — consider follow-up | N33: No reply | O33: Second-touch note (week1-followups.md template)
A34: QC (French) | B34: Société généalogique canadienne-française | C34: Guy Matte | D34: Président | E34: info@sgcf.com | F34: 1 | G34: 2026-08-06 | H34: r-8943475592269747230 | I34: Yes | J34: No | K34: 2026-08-20 | L34: French-language society — consider bilingual follow-up if no response. ⚠️ No reply after 2 weeks — consider follow-up | N34: No reply | O34: Second-touch note (week1-followups.md template)
A35: NL | B35: Family History Society of Newfoundland & Labrador | C35: Janet Morrissey | D35: President | E35: president@fhsnl.ca | F35: 1 | G35: 2026-08-06 | H35: r5003397084055165389 | I35: Yes | J35: No | K35: 2026-08-20 | L35: ⚠️ No reply after 2 weeks — consider follow-up | N35: No reply | O35: Second-touch note (week1-followups.md template)
A36: GA (Marietta) | B36: Cobb County Genealogical Society | C36: (President) | E36: via cobbgagensoc.org/contact-us | F36: 2 | I36: No | J36: No | L36: Contact form only — manual outreach required | N36: Not sent | O36: Manual: contact form
A37: GA (Augusta) | B37: Augusta Genealogical Society | C37: (President) | E37: augustagensociety@comcast.net | F37: 2 | G37: 2026-08-06 | H37: r3326249766627924885 | I37: Yes | J37: No | K37: 2026-08-20 | L37: ⚠️ No reply after 2 weeks — consider follow-up | N37: No reply | O37: Second-touch note (week1-followups.md template)
A38: GA (East Georgia) | B38: East Georgia Genealogical Society | C38: (President) | E38: gaeggs@yahoo.com | F38: 2 | G38: 2026-08-06 | H38: r5060624238695126661 | I38: Yes | J38: No | K38: 2026-08-20 | L38: ⚠️ No reply after 2 weeks — consider follow-up | N38: No reply | O38: Second-touch note (week1-followups.md template)
A39: GA (SW Georgia) | B39: Southwest Georgia Genealogical Society | C39: (President) | E39: lalford@docolib.org | F39: 2 | G39: 2026-08-06 | H39: r-6826650153058857107 | I39: Yes | J39: No | K39: 2026-08-20 | L39: ⚠️ No reply after 2 weeks — consider follow-up | N39: No reply | O39: Second-touch note (week1-followups.md template)
A40: MN (Anoka) | B40: Anoka County Genealogical Society | C40: (President) | E40: acgsmn@yahoo.com | F40: 2 | G40: 2026-08-06 | H40: r5361454840296291781 | I40: Yes | J40: No | K40: 2026-08-20 | L40: ⚠️ No reply after 2 weeks — consider follow-up | N40: No reply | O40: Second-touch note (week1-followups.md template)
A41: NC (Guilford) | B41: Guilford County Genealogical Society | C41: (President) | E41: gcgsoc@yahoo.com | F41: 2 | G41: 2026-08-06 | H41: r4712748195779489175 | I41: Yes | J41: No | K41: 2026-08-20 | L41: ⚠️ No reply after 2 weeks — consider follow-up | N41: No reply | O41: Second-touch note (week1-followups.md template)
...

Sheet Creators
A1: Type | B1: Show / channel | C1: Host | D1: Contact route | E1: Prior contact | F1: Pitch date (plan) | G1: Hook / pitch ref | H1: Warm-up started | I1: Pitched (date) | J1: Replied? | K1: Outcome / notes
A2: Podcast | B2: Research Like a Pro | C2: Diana Elder & Nicole Dyer | D2: familylocket.com/contact-us (guest requests) | E2: 2026-07-03 form; DECLINED 07-13 (beta-swamped, 'exhibit at RootsTech') | F2: 2026-09-21 | G2: Second approach; pitch in week3-podcast-pitches.md §1
A3: Podcast | B3: The Genealogy Guys | C3: George Morgan & Drew Smith | D3: genealogyguys@gmail.com | E3: none | F3: 2026-09-21 | G3: Review-copy pitch §4
A4: Podcast | B4: Genealogy Gems | C4: Lisa Louise Cooke | D4: lisalouisecooke.com/contact | E4: none | F4: 2026-09-22 | G4: Tree Crossing-shaped demo §2
A5: Podcast | B5: Family Tree Magazine Podcast | C5: Andrew Koch | D5: FamilyTree@Yankeepub.com | E5: none | F5: 2026-09-22 | G5: Tool-creator interview §3
A6: Podcast | B6: The Family History AI Show | C6: Mark Thompson & Steve Little | D6: makingfamilyhistory.com/contact | E6: none | F6: 2026-09-23 | G6: Founder/design-rules pitch §5
A7: Podcast (bench) | B7: French-Canadian Legacy Podcast | C7: Jesse Martineau & Mike Campbell | D7: fclpodcast.com/contact | E7: none | G7: Acadian register segment
A8: Podcast (bench) | B8: DearMYRTLE | C8: Pat Richley-Erickson | D8: dearmyrtle.substack.com | E8: none | G8: Live demo; small reach
A9: Newsletter | B9: Amy Johnson Crow | C9: Amy Johnson Crow | D9: ajc@amyjohnsoncrow.com | E9: 2026-07-03 email, no reply | G9: Newsletter mention only (podcast ended 2022)
A10: YouTube | B10: Family History Hound | C10: Ellen Thompson-Jennings | D10: info@familyhistoryhound.com | E10: none | F10: after 2-wk warm-up | G10: 'Step by Step: Acadians vs the 1755 rolls'
A11: YouTube | B11: Chronicle Makers | C11: Denyse Allen | D11: denyseallen.substack.com (message) | E11: none | F11: after 2-wk warm-up | G11: 'Does one story a day pass the Chronicle Makers test'
A12: YouTube | B12: DNA Family Trees | C12: Larry Jones | D12: YouTube About / mailing list | E12: none | F12: after 2-wk warm-up | G12: '22 checks before you trust ThruLines' (follows his Stemma videos)
A13: YouTube | B13: Have Roots, Will Travel | C13: Lisa Elvin-Staltari | D13: haverootswilltravel.com | E13: none | F13: after 2-wk warm-up | G13: 'FDR bonus: Filles du Roi tree vs passenger lists'
A14: YouTube | B14: Tech for Senior | C14: Ron Brown & Hewie Poplock | D14: hewie.net/contact-us | E14: none | F14: after 2-wk warm-up | G14: 'Genealogy on the iPad, no desktop software'
A15: YouTube (alt) | B15: Projectkin | C15: Barbara Tien | D15: projectkin.substack.com (message ringleader) | E15: none | G15: 'At the stone' Project Recipe
A16: Blog | B16: Genea-Musings | C16: Randy Seaver | D16: (blog contact) | E16: none | G16: Daily blogger; strong blog target

Sheet Communities
A1: Platform | B1: Group / post | C1: Size | D1: Posture | E1: Joined / requested | F1: Approved / posted (date) | G1: Notes | H1: Replies / comments | I1: Sign-ups attributed
A2: Facebook | B2: Genealogy and Artificial Intelligence (AI) | C2: 27.2K | D2: JOIN NOW — post as builder, disclosed | E2: 2026-09-09 requested | G2: Only group where apps are on-topic
A3: Facebook | B3: Mayflower Descendants!!!! | C3: 91.8K | D3: JOIN NOW | E3: 2026-09-09 requested | G3: Passenger-list story
A4: Facebook | B4: Acadian Genealogy | C4: 10.7K | D4: JOIN NOW | E4: 2026-09-09 requested | G4: Doiron/Pisiquid story
A5: Facebook | B5: New England Family Genealogy and History | C5: 18K | D5: JOIN NOW | E5: 2026-09-09 requested | G5: Colonial / Towne story
A6: Facebook | B6: The Civil War Genealogy and Research Forum | C6: 11.4K | D6: JOIN NOW (1 post/mo) | E6: 2026-09-09 requested | G6: Regiment-from-headstone story
A7: Facebook | B7: The Genealogy Squad | C7: 74K | D7: READ ONLY — never name the app | E7: 2026-09-09 requested
A8: Facebook | B8: Family Tree Maker® Users | C8: 28.4K | D8: READ ONLY — no competitor mentions | E8: 2026-09-09 requested | G8: Listening post for export/media questions
A9: Facebook | B9: RootsMagic Users | C9: 25.7K | D9: READ ONLY | E9: 2026-09-09 requested | G9: GEDCOM pain points
A10: Reddit | B10: r/Genealogy — Post 1 headstones (Jemima/Jemenice, Asa's date, Melvina) | C10: 207K | D10: Post under own name, no link | F10: 2026-09-14 (plan) | G10: Confirm naming Melvina
A11: Reddit | B11: r/Genealogy — Post 2 draft ≠ service (Huntington, Edwin Parker) | C11: 207K | D11: Post under own name, no link | F11: 2026-09-17 (plan) | G11: Confirm naming F.M. Huntington
A12: Reddit | B12: r/Genealogy + r/Acadian — Post 3 wrong roll (Doiron, Duke William) | C12: 207K | D12: Post under own name, no link | F12: 2026-09-21 (plan) | G12: Confirm Acadian line is Ruth's side

Sheet Weekly Review
A1: Week of | B1: Emails sent | C1: Replies | D1: Comps granted | E1: Trial starts (RevenueCat) | F1: Paid conversions | G1: What worked / decisions
A2: 2026-09-14
A3: 2026-09-21
A4: 2026-09-28
A5: 2026-10-05
A6: 2026-10-12
A7: 2026-10-19
A9: Fill Fridays from Gmail (sent/replies), the Operator Ledger (witnesslives.com/operator), and RevenueCat.

Sheet UTM Legend
A1: Witness Marketing — UTM Naming Convention
A2: Blue cells = edit/fill in. Black = fixed convention. Copy a row's formula in B when building a new link.
A4: Parameter | B4: Purpose | C4: Allowed values (Phase 1) | D4: Example
A5: utm_source | B5: Where the click came from | C5: reddit | facebook | tiktok | producthunt | podcast-<slug> | society-tier1 | society-tier2 | society-tier3 | email | mackiev | D5: society-tier2
A6: utm_medium | B6: Type of channel | C6: social | community | video | referral | email | outreach | pr | D6: outreach
A7: utm_campaign | B7: Which phase/push this belongs to | C7: witness-phase1 | D7: witness-phase1
A8: utm_content | B8: Specific post/email/video, for A/B comparison | C8: free text slug, e.g. week2-post1, clip-storyreveal-1, olde-meck-followup | D8: olde-meck-followup
A10: Two tracking tracks — read this first
A11: WEB APP (app.witnesslives.com): standard UTM tracking works end-to-end — click, sign-up, and Stripe/RevenueCat Web Billing conversion all happen in-browser. Use full UTM URLs for every web-funnel link.
A12: iOS APP STORE: UTM parameters do NOT survive the jump into the App Store app, so a plain UTM link only tells you the click happened, not the resulting trial/conversion. Use Apple's App Store Connect Custom Product Pages instead — each gets its own trackable URL, and App Analytics reports downloads per link, natively and for free.
A13: Practical rule: for any post/pitch driving to the App Store, create (or reuse) a Custom Product Page per channel (e.g. one for Reddit, one for podcasts) and use that page's unique URL as the link. Log the page name in the 'App Store Funnel Tracker' tab.
A14: Example web link format: https://app.witnesslives.com/?utm_source=reddit&utm_medium=social&utm_campaign=witness-phase1&utm_content=week2-post1

Sheet Web Funnel Tracker
A1: Web App Funnel (app.witnesslives.com) — fill blue cells weekly
A2: Sample numbers removed 2026-09-09 — every row below is real or empty. Web UTM capture is NOT yet built in the app; fill Visits only once it is.
A3: Week Of | B3: Source | C3: Medium | D3: Campaign | E3: Content | F3: Full UTM Link | G3: Visits | H3: Trial Starts | I3: Paid Conversions | J3: Visit→Trial % | K3: Trial→Paid %
J4: =IFERROR(H4/G4,0) | K4: =IFERROR(I4/H4,0)
J5: =IFERROR(H5/G5,0) | K5: =IFERROR(I5/H5,0)
J6: =IFERROR(H6/G6,0) | K6: =IFERROR(I6/H6,0)
J7: =IFERROR(H7/G7,0) | K7: =IFERROR(I7/H7,0)
J8: =IFERROR(H8/G8,0) | K8: =IFERROR(I8/H8,0)
J9: =IFERROR(H9/G9,0) | K9: =IFERROR(I9/H9,0)
J10: =IFERROR(H10/G10,0) | K10: =IFERROR(I10/H10,0)
J11: =IFERROR(H11/G11,0) | K11: =IFERROR(I11/H11,0)
J12: =IFERROR(H12/G12,0) | K12: =IFERROR(I12/H12,0)
J13: =IFERROR(H13/G13,0) | K13: =IFERROR(I13/H13,0)
J14: =IFERROR(H14/G14,0) | K14: =IFERROR(I14/H14,0)
J15: =IFERROR(H15/G15,0) | K15: =IFERROR(I15/H15,0)
... J19: =IFERROR(H19/G19,0) | K19: =IFERROR(I19/H19,0)
B20: TOTAL | G20: =SUM(G4:G19) | H20: =SUM(H4:H19) | I20: =SUM(I4:I19) | J20: =IFERROR(H20/G20,0) | K20: =IFERROR(I20/H20,0)

Sheet App Store Funnel Tracker
A1: App Store Funnel — one row per Custom Product Page / channel
A2: Sample numbers removed 2026-09-09 — every row below is real or empty. Web UTM capture is NOT yet built in the app; fill Visits only once it is.
A3: Week Of | B3: Source | C3: Custom Product Page Name | D3: Product Page URL | E3: Impressions | F3: Downloads (App Analytics) | G3: Trial Starts (RevenueCat) | H3: Paid Conversions (RevenueCat)
B20: TOTAL | E20: =SUM(E4:E19) | F20: =SUM(F4:F19) | G20: =SUM(G4:G19) | H20: =SUM(H4:H19)
A22: Note: Custom Product Pages are set up in App Store Connect (free, native). Impressions/downloads come from App Analytics; match Trial Starts/Conversions from RevenueCat by date range since Apple doesn't pass UTM-level attribution automatically.

Sheet Goal Tracker
A1: Progress to 100 Paid Subscribers (Witness) by Dec 31, 2026
A3: Week Of | B3: New Paid (Web) | C3: New Paid (App Store) | D3: Cumulative Paid | E3: % to Goal (100)
A4: 2026-09-14 | B4: ='Web Funnel Tracker'!I4 | C4: ='App Store Funnel Tracker'!H4 | D4: =SUM(B4:C4) | E4: =D4/100
B5: ='Web Funnel Tracker'!I5 | C5: ='App Store Funnel Tracker'!H5 | D5: =SUM(B5:C5)+D4 | E5: =D5/100
B6: ='Web Funnel Tracker'!I6 | C6: ='App Store Funnel Tracker'!H6 | D6: =SUM(B6:C6)+D5 | E6: =D6/100
B7: ='Web Funnel Tracker'!I7 | C7: ='App Store Funnel Tracker'!H7 | D7: =SUM(B7:C7)+D6 | E7: =D7/100
B8: ='Web Funnel Tracker'!I8 | C8: ='App Store Funnel Tracker'!H8 | D8: =SUM(B8:C8)+D7 | E8: =D8/100
B9: ='Web Funnel Tracker'!I9 | C9: ='App Store Funnel Tracker'!H9 | D9: =SUM(B9:C9)+D8 | E9: =D9/100
B10: ='Web Funnel Tracker'!I10 | C10: ='App Store Funnel Tracker'!H10 | D10: =SUM(B10:C10)+D9 | E10: =D10/100
B11: ='Web Funnel Tracker'!I11 | C11: ='App Store Funnel Tracker'!H11 | D11: =SUM(B11:C11)+D10 | E11: =D11/100
B12: ='Web Funnel Tracker'!I12 | C12: ='App Store Funnel Tracker'!H12 | D12: =SUM(B12:C12)+D11 | E12: =D12/100
B13: ='Web Funnel Tracker'!I13 | C13: ='App Store Funnel Tracker'!H13 | D13: =SUM(B13:C13)+D12 | E13: =D13/100
B14: ='Web Funnel Tracker'!I14 | C14: ='App Store Funnel Tracker'!H14 | D14: =SUM(B14:C14)+D13 | E14: =D14/100
B15: ='Web Funnel Tracker'!I15 | C15: ='App Store Funnel Tracker'!H15 | D15: =SUM(B15:C15)+D14 | E15: =D15/100
B16: ='Web Funnel Tracker'!I16 | C16: ='App Store Funnel Tracker'!H16 | D16: =SUM(B16:C16)+D15 | E16: =D16/100
... B19: ='Web Funnel Tracker'!I19 | C19: ='App Store Funnel Tracker'!H19 | D19: =SUM(B19:C19)+D18 | E19: =D19/100
